Workbook

Sheet About
A1: Seven Elements of ZTA — ZPA requirements matrix
A2: Built 2026-10-20. Every requirement the book places on private application access, mapped to the Private Access (ZPA) capability that meets it and the help.zscaler.com article that documents it.
A4: Document
A5: Type / scope / status | B5: reference · general, with tenant-specific project notes (as in reference/glossary.md) · draft
A6: Updated | B6: 2026-10-20
A7: Sources | B7: The book (below) and every article on the ‘Help articles’ sheet, each read on the date shown there.
A9: Source
A10: Book | B10: Seven Elements of Highly Successful Zero Trust Architecture — An Architect’s Guide to the Zscaler Zero Trust Exchange. Nathan Howe, Sanjit Ganguli, Gerard Festa. Third edition, January 2024. ISBN 979-8-9871864-1-1.
A11: File | B11: reference/seven-elements-of-highly-successful-zta.pdf (154 PDF pages). Printed page = PDF page − 2.
A12: Nature of the source | B12: Vendor-authored. Its requirements are framed around Zscaler’s own architecture, so a high ‘Native’ count is expected and is not independent evidence of fitness for this estate. Use the matrix as a checklist of design principles and a map to the docs, not as an evaluation.
A14: Method
A15: Extraction | B15: All 154 pages read. A row is a requirement the book places on private (internal) application access, or on the platform where ZPA must meet it. Statements repeated across elements are consolidated into one row with every page that states them. Pro tips and recommendations are kept as Type = Guidance.
A16: Book basis | B16: Verbatim quotes, each checked by script against the PDF text layer; the page columns are generated from where each quote occurs plus other pages that restate the same requirement.
A17: Help articles | B17: Every cited article was opened and read on 2026-10-20. help.zscaler.com is a JavaScript application, so pages were rendered (not fetched raw) and the canonical URL after redirects is recorded. The evidence column quotes the article verbatim. Where no article supports a requirement, the row says so rather than citing a near miss.
A18: Naming | B18: The help centre now titles the product ‘Private Access (ZPA)’ and the console the ‘Zscaler Admin Console’; this matrix uses the current names. Some features the book describes have been renamed or extended since January 2024.
A19: Out of scope | B19: Book requirements that belong to other Zscaler products (Internet & SaaS/ZIA, ZDX, CASB, Posture Control) are listed on the ‘Not ZPA’ sheet for completeness, without help articles.
A21: Fit legend
A22: Native | B22: A Private Access (ZPA) capability meets the requirement as the book states it.
A23: Partial | B23: ZPA meets part of it; the rest needs design work, another component, or is not documented. The ‘How ZPA meets it’ column names the gap.
A24: Other Zscaler product | B24: Met by a Zscaler product outside ZPA that integrates with ZPA policy or traffic (Branch/Cloud Connector, Deception, Microsegmentation, Internet & SaaS risk scoring). Usually a separate licence.
A25: Dependency | B25: Met outside Zscaler (IdP, EDR, the customer’s own classification); ZPA consumes the result.
A26: Gap | B26: No ZPA capability found in the help centre. Absence from the docs is evidence, not proof — confirm with Zscaler before designing around it.
A27: Not in help centre | B27: Commercial or assurance property (SLA, tenancy); evidence comes from contract or assurance documents, not the help centre.
A29: Columns worth knowing
A30: Project note | B30: Tenant-specific. Facts recorded in this repo (README, decisions, discovery, backlog, glossary) with their reference, or a statement explicitly labelled Inferred / Open. Blank means the repo records nothing that bears on the row.
A31: Constraints | B31: Only what the cited article states (licences, prerequisites, limited availability). Blank means none stated in the article read — not that none exist.
A32: Fit | B32: Drop-down. Edit it as the design firms up; the Summary sheet recounts.
A34: Counts
A35: Requirement rows | B35: =COUNTA(Requirements!A2:A70) -> 69
A36: Rows not met by ZPA (Not ZPA sheet) | B36: =COUNTA('Not ZPA'!A2:A24) -> 23
A37: Help articles cited | B37: =COUNTA('Help articles'!A2:A98) -> 97

Sheet Requirements
A1: ID | B1: Book section | C1: Theme | D1: Type | E1: Requirement (normalised from the book) | F1: Book basis (verbatim) | G1: Book pages (printed) | H1: PDF pages | I1: ZPA feature / capability | J1: How ZPA meets it | K1: Fit | L1: Primary help article | M1: Primary article URL | N1: Supporting help articles | O1: Help-centre evidence (verbatim) | P1: Constraints / prerequisites stated in the docs | Q1: Project note (this estate) | R1: Article verified
A2: ZT-01 | B2: Overview of zero trust | C2: Architecture | D2: Requirement | E2: Grant no implicit trust from network location or asset ownership: access is granted only after identity and context are verified and policy is enforced (least privilege). | F2: “trust is only granted once identity and context are verified and policy checks are enforced” | G2: 11, 27 | H2: 13, 29 | I2: Brokered user-to-application access; implicit block in access policy | J2: ZPA never grants network access: a user reaches only the applications an access policy rule allows, after IdP authentication through Client Connector. With no matching rule, access is implicitly blocked. | K2: Native | L2: What Is Zscaler Private Access? | M2: https://help.zscaler.com/zpa/what-zscaler-private-access | N2: Understanding Policies — https://help.zscaler.com/zpa/understanding-policies Understanding the Private Access Architecture — https://help.zscaler.com/zpa/understanding-private-access-architecture | O2: [What Is Zscaler Private Access?] “With Private Access, application access does not require network access.” [Understanding Policies] “For access policy, access to the application is implicitly set to Block Access. This is also the case if you do not define any policy rules at all within the Zscaler Admin Console.” | Q2: README objective: ‘No user or workload can reach a service it has no policy for.’ The workload half is deferred: east-west is out of scope (decision 2026-09-19). | R2: 2026-10-20
A3: ZT-02 | B3: Overview of zero trust | C3: Architecture | D3: Requirement | E3: Private applications must be invisible to unauthorised initiators: not exposed to the internet or to connected networks, and not discoverable (no services, FQDNs or IPs) until policy permits access. | F3: “Apps are invisible (sit behind Zscaler controls) and can’t be discovered from unauthorized sources (internet or connected networks)” “for private apps–cannot even see that the requested application exists” | G3: 12, 52, 116, 124, 133, 145 | H3: 14, 54, 118, 126, 135, 147 | I3: App Connectors (outbound-only) behind the Service Edge broker | J3: Applications sit behind App Connectors that only dial out to a Public or Private Service Edge, so nothing about the app is published to the internet through ZPA, and Zscaler describes apps as invisible and unroutable to all but authorised users. ZPA does not remove other routes to the app (LAN, cloud public IPs) — those must be closed separately for the invisibility claim to hold. | K3: Partial | L3: What Is Zscaler Private Access? | M3: https://help.zscaler.com/zpa/what-zscaler-private-access | N3: About App Connectors — https://help.zscaler.com/zpa/about-connectors Understanding the Private Access Architecture — https://help.zscaler.com/zpa/understanding-private-access-architecture Private Service Edge Deployment Prerequisites — https://help.zscaler.com/zpa/service-edge-deployment-prerequisites | O3: [What Is Zscaler Private Access?] “Private Access renders your applications invisible to all but the authorized users and unroutable to anyone.” [About App Connectors] “App Connectors only connect outbound; they do not need any inbound open ports to operate correctly.” | P3: [Private Service Edge Deployment Prerequisites] “Your firewalls must be configured to let the Private Service Edge establish outbound connections to the IP addresses of the Public Service Edge for Private Access, and establish inbound connections from App Connectors and Zscaler Client Connector.” | Q3: current-state.md: Azure/AWS-hosted apps may already be reachable directly from the internet; a ZPA segment hides nothing unless that path is closed too. See also ZT-59 — on the LAN, invisibility holds only where direct routes are closed. | R3: 2026-10-20
A4: ZT-03 | B4: Overview of zero trust | C4: Segmentation | D4: Requirement | E4: Connect a specific authorised user to a specific authorised application, never to the network, so there is no routable path for lateral movement. | F4: “Connects a specific, authorized user to a specific, authorized resource” “users are given access not to networks, but to applications” | G4: 12, 124, 133, 145 | H4: 14, 126, 135, 147 | I4: Application segments + access policy (per-application brokering) | J4: Client Connector sends only traffic for defined application segments to Private Access (other traffic goes to Internet & SaaS or direct), and access policy decides which segments a user may reach. No network-level access is granted. | K4: Native | L4: What Is Zscaler Private Access? | M4: https://help.zscaler.com/zpa/what-zscaler-private-access | N4: Understanding the Private Access Architecture — https://help.zscaler.com/zpa/understanding-private-access-architecture About Access Policy — https://help.zscaler.com/zpa/about-access-policy | O4: [What Is Zscaler Private Access?] “With Private Access, application access does not require network access.” [Understanding the Private Access Architecture] “Zscaler Client Connector identifies internal applications to forward traffic to Private Access, and other traffic goes to Internet & SaaS.” | Q4: For a load-balanced app ZPA brokers user → VIP only; VIP → pool member and server-to-server legs keep today’s reachability (decision 2026-09-19; glossary ‘Virtual IP’). | R4: 2026-10-20
A5: ZT-04 | B5: Overview of zero trust | C5: Segmentation | D5: Requirement | E5: Enforce user-to-application segmentation through identity-aware policy that is independent of network segmentation (VLANs, subnets, firewall rules); the network is transport only. | F5: “not reliant on rigid network segmentation” “User-to-application segmentation can therefore be achieved not based on cumbersome network controls but rather by identity-aware policies.” | G5: 11, 18, 51, 124, 126 | H5: 13, 20, 53, 126, 128 | I5: Access policy on identity criteria (SAML/SCIM attributes, SCIM groups) against segments and segment groups | J5: Rules are written against who the user is (IdP attributes and groups) and which application segments or segment groups they may use — role-based access control — not against source subnets or VLANs. | K5: Native | L5: About Access Policy | M5: https://help.zscaler.com/zpa/about-access-policy | N5: Configuring Access Policies — https://help.zscaler.com/zpa/configuring-access-policies About SAML Attributes — https://help.zscaler.com/zpa/about-saml-attributes | O5: [About Access Policy] “Access policy rules enable you to implement role-based access control. To configure an access policy rule, you must first define the users and then define which applications or segment groups they can access.” | P5: [Configuring Access Policies] “In order for Private Access to process SAML and SCIM criteria in a rule, you must enable the SAML Attributes for Policy setting for SAML and the SCIM Attributes and Groups for Policy setting for SCIM when configuring an IdP.” | Q5: README: reachability by identity + posture, not source IP or VLAN. Glossary ‘ACL’: an app enforcing its own source-IP ACL sees the App Connector’s address, so it stops distinguishing users — for every user at once, at cutover. | R5: 2026-10-20
A6: ZT-05 | B6: Overview of zero trust | C6: Third-party & B2B | D6: Requirement | E6: Give third parties and B2B partners (contractors, suppliers, customers, users outside the primary authentication domain) application-level access under the same identity-based policy, without network access, and treat them as a separate risk population from employees. | F6: “third-party access, workload-to-workload, and location-to-location segmentation” “Validated external user (not part of primary auth domain)” | G6: 18, 37, 44, 74, 129, 148 | H6: 20, 39, 46, 76, 131, 150 | I6: B2B Federation; multiple IdPs; Browser Access and PRA for third parties | J6: Two documented models. (1) Third-party users sign in through an IdP the tenant trusts (up to 10 IdP configurations) and get application-level access policy like employees. (2) B2B Federation: a host tenant shares hostname-based segments with a guest partner’s ZPA tenant; guest users sign in with their own IdP via Client Connector, and only the guest admin writes the access policy for shared apps (the host sees it read-only). Browser Access and PRA give contractors clientless options. | K6: Native | L6: Understanding Business-to-Business (B2B) Federation | M6: https://help.zscaler.com/zpa/understanding-business-business-b2b-federation | N6: Configuring an IdP for Single Sign-On — https://help.zscaler.com/zpa/configuring-idp-single-sign About Browser Access — https://help.zscaler.com/zpa/about-browser-access Understanding Privileged Remote Access — https://help.zscaler.com/zpa/understanding-privileged-remote-access | O6: [Understanding Business-to-Business (B2B) Federation] “The user authenticates into Zscaler Client Connector using their standard corporate (guest tenant) credentials. Zscaler Client Connector authentication is always tied to the guest partner's IdP.” [Understanding Business-to-Business (B2B) Federation] “Only the guest partner admin can define, configure, and modify access policies to allow guest partners access to the shared host partner applications. The host partner has read-only access to view the policies configured by the guest partner.” [Configuring an IdP for Single Sign-On] “Within the Zscaler Admin Console, you can add up to 10 IdP configurations for single sign-on (SSO).” | P6: [Understanding Business-to-Business (B2B) Federation] “This feature is in limited availability, and requires a Private Access (ZPA) Federation license.” [Understanding Business-to-Business (B2B) Federation] “Both the host and guest partners must originate from the same cloud.” [Understanding Business-to-Business (B2B) Federation] “B2B Federation supports only user-to-application access between two partners using Zscaler Client Connector.” [Understanding Business-to-Business (B2B) Federation] “Only application segments with hostname-based configurations can be federated.” | Q6: Network 2 (Entra-only) needs ‘federated Zscaler B2B access’ to ~10 AD-authenticating core apps (current-state.md); ruling: each must be uplifted to modern auth (decision 2026-09-27); ZPA must still identify network 2 users (T-059). If that means ZPA B2B Federation: both tenants on the same Zscaler cloud, hostname-based segments only, Client Connector only, and the network 2 admin writes the access policy for shared apps (help article). | R6: 2026-10-20
A7: ZT-06 | B7: Connecting to the Zero Trust Exchange | C7: Connectivity | D7: Requirement | E7: Provide an endpoint agent that maintains a persistent control plane and dynamic, per-application data-plane tunnels for internal applications, and is the same single agent used for internet/SaaS traffic. | F7: “persistent control plane and dynamic, microsegmented data plane tunnels to the Zero Trust Exchange for the purpose of internal app protection” | G7: 23, 136 | H7: 25, 138 | I7: Zscaler Client Connector (one agent for Internet & SaaS and Private Access) | J7: Client Connector carries Internet & SaaS and Private Access traffic from one agent; its forwarding profile sets how ZPA traffic is treated per network type, and it identifies internal applications to forward to Private Access. | K7: Native | L7: What Is Zscaler Client Connector? | M7: https://help.zscaler.com/zscaler-client-connector/what-is-zscaler-client-connector | N7: Configuring Forwarding Profiles for Zscaler Client Connector — https://help.zscaler.com/zscaler-client-connector/configuring-forwarding-profiles-zscaler-client-connector Understanding the Private Access Architecture — https://help.zscaler.com/zpa/understanding-private-access-architecture | O7: [What Is Zscaler Client Connector?] “Using Zscaler Client Connector, users can get all of the benefits of the Zscaler service for internet traffic, as well as granular, policy-based access to internal resources from a single point.” [Configuring Forwarding Profiles for Zscaler Client Connector] “The forwarding profile tells Zscaler Client Connector how to treat traffic from your users' systems in different network environments for the Internet & SaaS and Private Access services.” | P7: [What Is Zscaler Client Connector?] “If you are using the app for Private Access, your organization must use SAML authentication.” | Q7: Browser Access is out of scope, so every ZPA user needs Client Connector on an enrolled device (decision 2026-09-27). | R7: 2026-10-20
A8: ZT-07 | B8: Connecting to the Zero Trust Exchange | C8: Connectivity | D8: Requirement | E8: Where an agent cannot be installed (servers, IoT/OT, whole sites, cloud workloads), forward traffic into the platform from the site or cloud (GRE/IPsec, branch or cloud connector form factors). | F8: “customers can leverage site-based forwarding options (GRE or IPSEC tunnels) to connect entire sites to the Zero Trust Exchange” | G8: 23, 46, 137, 146, 148 | H8: 25, 48, 139, 148, 150 | I8: Branch Connector and Cloud Connector forwarding into Private Access; their groups as policy criteria | J8: Branch Connector (sites) and Cloud Connector (cloud workloads) are VMs that forward traffic to Internet & SaaS and Private Access; Branch/Cloud Connector groups and client types can be matched in access policy. The articles read do not mention IoT. | K8: Other Zscaler product | L8: About Branch Connectors | M8: https://help.zscaler.com/zpa/about-branch-connectors | N8: About Cloud Connectors — https://help.zscaler.com/zpa/about-cloud-connectors About Branch Connector Groups — https://help.zscaler.com/zpa/about-branch-connector-groups About Cloud Connector Groups — https://help.zscaler.com/zpa/about-cloud-connector-groups About Access Policy — https://help.zscaler.com/zpa/about-access-policy Understanding Business Continuity — https://help.zscaler.com/zpa/understanding-business-continuity | O8: [About Branch Connectors] “Branch Connectors are virtual machine (VM) images that simplify traffic forwarding to Zscaler services (i.e., Internet & SaaS (ZIA) and Private Access (ZPA)) without using shared server software.” [About Cloud Connectors] “Secure workload traffic to the internet and provide seamless connectivity to private applications in other cloud regions or data centers.” | P8: [Understanding Business Continuity] “Browser Access, Source IP Anchoring, Cloud Connector, and Branch Connector client types are not supported.” (Business Continuity mode — see ZT-64.) | Q8: Glossary: Branch Connector and Cloud Connector are not part of ZPA and are licensed separately; they are the documented routes for traffic with no Client Connector (servers, IoT, OT, payment terminals). Branch Connector’s Direct action leaves no ZPA record. EFTPOS may not tolerate brokering and may use IP literals (current-state.md; T-016). | R8: 2026-10-20
A9: ZT-08 | B9: Connecting to the Zero Trust Exchange | C9: Clientless & privileged access | D9: Requirement | E9: Give unmanaged devices that cannot run an agent clientless access through a protected portal reached by DNS CNAME, after IdP authentication, without direct interaction with the application. | F9: “DNS CNAME redirects traffic to a protected, private portal. Users then authenticate against an IdP to access web, RDP-based, and SSH-based applications.” | G9: 23, 43, 44 | H9: 25, 45, 46 | I9: Browser Access (web apps), Privileged Remote Access (RDP/SSH/VNC), user portal | J9: Browser Access delivers HTTP/HTTPS applications to a TLS 1.2 browser with no Client Connector, using a published CNAME and certificate per application; PRA covers RDP, SSH and VNC from the browser; a user portal lists the apps a user is allowed. | K9: Native | L9: About Browser Access | M9: https://help.zscaler.com/zpa/about-browser-access | N9: Understanding Privileged Remote Access — https://help.zscaler.com/zpa/understanding-privileged-remote-access Accessing a User Portal — https://help.zscaler.com/zpa/accessing-user-portal Configuring Defined Application Segments — https://help.zscaler.com/zpa/configuring-defined-application-segments About Applications — https://help.zscaler.com/zpa/about-applications | O9: [About Browser Access] “Browser Access allows you to leverage a web browser for user authentication and application access over Private Access (ZPA), without requiring users to install Zscaler Client Connector on their devices.” [About Browser Access] “Private Access supports HTTP and HTTPS protocols, and Private Access inserts a Via header in HTTP requests.” | P9: [About Browser Access] “Browser Access requires that the application server supports TLS 1.2 encryption.” [Configuring Defined Application Segments] “When defining applications for Browser Access, you can only configure FQDNs.” [About Applications] “Apply advanced capabilities that you are licensed for such as Browser Access, Zero Trust Browser, AppProtection, and data loss prevention.” | Q9: Out of scope: Browser Access is not enabled and no segment may use it (decision 2026-09-27). Unmanaged and partner-managed devices therefore have no ZPA path. | R9: 2026-10-20
A10: ZT-09 | B10: Connecting to the Zero Trust Exchange | C10: Connectivity | D10: Requirement | E10: Work over any underlying network, IPv4 or IPv6. | F10: “The network can be located anywhere and be built on IPv4 or IPv6” | G10: 22 | H10: 24 | I10: IPv4 and IPv6 support | J10: IPv4 is supported for TCP, UDP and ICMP. IPv6 applications are supported for TCP only; an IPv6 client reaching an IPv4 application works for TCP, UDP and ICMP. | K10: Partial | L10: Configuring IPv6 | M10: https://help.zscaler.com/zpa/configuring-ipv6 | N10: About App Connector Groups — https://help.zscaler.com/zpa/about-connector-groups | O10: [Configuring IPv6] “Private Access (ZPA) supports IPv4 for TCP-, UDP-, and ICMP-based connections, and supports IPv6 for only TCP-based applications.” [Configuring IPv6] “An IPv6 endpoint through Zscaler Client Connector to access an IPv4 application on the server is supported for TCP-, UDP-, and ICMP-based connections.” | P10: [Configuring IPv6] “Only TCP-based connections are supported for direct IPv6 communications from an App Connector to a server. UDP-based connections are not supported.” | R10: 2026-10-20
A11: ZT-10 | B11: Element 1 — Who is connecting? | C11: Identity | D11: Requirement | E11: Integrate with the enterprise IdP using standards (SAML; SCIM; OAuth named): the access service validates identity issued by the IdP rather than being the identity store. | F11: “a zero trust solution must have established integration with the enterprise IdP provider” “the zero trust solution is not the store of identity” | G11: 28, 29, 30, 32, 146 | H11: 30, 31, 32, 34, 148 | I11: IdP configuration (SAML 2.0, SP-initiated SSO); up to 10 IdPs; optional SCIM | J11: Users authenticate into Client Connector through any SAML 2.0 IdP (SP-initiated). ZPA keeps no hosted user database for SAML-only users — attributes travel in the SAML assertion; enabling SCIM adds provisioned users and groups. The book’s OAuth path has no counterpart in the ZPA user-IdP articles (OIDC appears only via Authentication Service — ZT-12). | K11: Native | L11: About IdP Configuration | M11: https://help.zscaler.com/zpa/about-idp-configuration | N11: Configuring an IdP for Single Sign-On — https://help.zscaler.com/zpa/configuring-idp-single-sign About SAML Attributes — https://help.zscaler.com/zpa/about-saml-attributes | O11: [About IdP Configuration] “For users to access your applications via Private Access (ZPA), they must first authenticate into Zscaler Client Connector using any SAML 2.0-compliant identity provider (IdP) with the service provider-initiated (SP initiated) model.” [About SAML Attributes] “Private Access does not use a hosted user database for provisioning, so user attributes within SAML assertions cannot be viewed within the Zscaler Admin Console.” | P11: [About IdP Configuration] “The IdP Configuration page is read only if you are subscribed to Authentication Service for users.” [Configuring an IdP for Single Sign-On] “If you update an IdP certificate, this change triggers an Authentication Error message in the Zscaler Client Connector for users and prevents access to your apps.” | Q11: Identity is split — Entra ID and on-prem AD, one-way AD → Entra sync (current-state.md). Inferred: the IdP ZPA authenticates against decides which attributes policy can use. | R11: 2026-10-20
A12: ZT-11 | B12: Element 1 — Who is connecting? | C12: Identity | D12: Requirement | E12: Receive identity changes from the IdP after login (provisioning, deprovisioning, group membership), not only the authentication result. | F12: “receive updates on changes to that verification” | G12: 30, 32 | H12: 32, 34 | I12: SCIM 2.0 provisioning of users, groups and attributes | J12: With SCIM enabled, disabling or deleting a user in the directory removes them from Private Access, and SCIM groups and attributes become policy criteria. What happens to sessions already open is not documented, and SAML-attribute changes apply only after the user re-authenticates. | K12: Native | L12: About SCIM | M12: https://help.zscaler.com/zpa/about-scim | N12: About SCIM Groups — https://help.zscaler.com/zpa/about-scim-groups Deleting Users in SCIM — https://help.zscaler.com/zpa/deleting-users-scim SCIM Configuration Guide for Microsoft Azure AD — https://help.zscaler.com/zpa/scim-configuration-guide-microsoft-azure-ad Configuring Timeout Policies — https://help.zscaler.com/zpa/configuring-timeout-policies | O12: [About SCIM] “Enabling SCIM allows the Zero Trust Exchange (ZTE) to quickly remove users from Private Access when a user is disabled or deleted in your user directory and to enforce policies based on SCIM attributes and SCIM groups.” [Configuring Timeout Policies] “In addition, if a configuration change is made on an IdP that also causes a change to the SAML assertion, then the updated assertion is applied to Private Access (ZPA) policies after the user reauthenticates.” | P12: [Deleting Users in SCIM] “Users accessing applications via Browser Access can not be removed from Private Access using SCIM.” [About SCIM] “Zscaler only supports SCIM version 2.0.” [SCIM Configuration Guide for Microsoft Azure AD] “After SCIM Sync is enabled, Zscaler recommends waiting a minimum of 48 hours, or up to a week, before enabling SCIM policies.” | Q12: backlog T-053: the onboarding triage search separates a SCIM sync gap from posture and DNS failures — provisioning lag surfaces as a failed first session. | R12: 2026-10-20
A13: ZT-12 | B13: Element 1 — Who is connecting? | C13: Identity | D13: Requirement | E13: Authenticate users with at least multifactor authentication. | F13: “Zscaler recommends a minimum of MFA be used to validate users” | G13: 30 | H13: 32 | I13: MFA at the IdP; step-up authentication (Conditional Access action, Authentication Service) | J13: ZPA delegates authentication to the IdP, so MFA is the IdP’s policy. ZPA can demand stronger authentication for sensitive apps only through step-up authentication (authentication levels), which needs an Authentication Service subscription and an OIDC-based external IdP. Zscaler’s AD FS guide (a step marked for AD FS 3.0) selects ‘I do not want to configure multi-factor authentication settings…’ for the relying-party trust, so MFA has to be enforced elsewhere in that design. | K13: Dependency | L13: Configuring Access Policies | M13: https://help.zscaler.com/zpa/configuring-access-policies | N13: Understanding Step-Up Authentication — https://help.zscaler.com/authentication-service/understanding-step-up-authentication Configuration Guide for Microsoft ADFS 2.0 and 3.0 — https://help.zscaler.com/zpa/configuration-guide-microsoft-adfs-20-and-30 | O13: [Configuring Access Policies] “Step-up authentication enforces stronger authentication and only provides access to applications when the authentication matches the additional authentication levels.” [Configuring Access Policies] “Conditional Access: Allows access to sensitive resources for step-up authentication, and is only an option if you are subscribed to Authentication Service.” | P13: [Understanding Step-Up Authentication] “Step-up authentication is supported only with OIDC-based external IdP integrations.” | R13: 2026-10-20
A14: ZT-13 | B14: Element 1 — Who is connecting? | C14: Identity | D14: Requirement | E14: Consume IdP-supplied identity values (groups, department, OU, email, employee ID, geography) chosen by the customer, and use them to differentiate users in policy. | F14: “consume IdP-provided values of identity, certificates, and shared details, including departments, groups, organizational units (OUs), email addresses, etc.” | G14: 30, 31, 33, 42 | H14: 32, 33, 35, 44 | I14: SAML attributes, SCIM attributes and SCIM groups as access-policy criteria | J14: Admins import the SAML attributes they want, or receive users/groups/attributes by SCIM, and use them as rule criteria; ZPA’s assertion can carry more authorisation attributes than Internet & SaaS. SCIM brings a fixed attribute set (no custom attributes). Silent failure: if the IdP’s ‘Attributes for Policy’ setting is off, rules using those criteria are not evaluated. | K14: Native | L14: About SAML Attributes | M14: https://help.zscaler.com/zpa/about-saml-attributes | N14: About SCIM — https://help.zscaler.com/zpa/about-scim About SCIM Groups — https://help.zscaler.com/zpa/about-scim-groups Configuring Access Policies — https://help.zscaler.com/zpa/configuring-access-policies Understanding Policies — https://help.zscaler.com/zpa/understanding-policies | O14: [About SAML Attributes] “You must configure SAML attributes to use them when defining policy rule criteria.” [About SAML Attributes] “In Private Access, various authorization attributes can be provided by the IdP to the Zscaler Client Connector in the SAML assertion, unlike Internet & SaaS, where SAML assertions are restricted to user identity, group, and department attributes.” | P14: [About SCIM] “TheSCIM Attributes page is a read-only table, and Private Access does not support custom attributes. [sic]” [Understanding Policies] “Using NameID as a SAML attribute within access and timeout policy rules is not supported.” | Q14: README lever: tight criteria = IdP group / SCIM attribute / posture; loose = ‘any authenticated user’. | R14: 2026-10-20
A15: ZT-14 | B15: Element 1 — Who is connecting? | C15: Identity | D15: Requirement | E15: Support the common enterprise IdPs: Microsoft Entra ID (Azure AD) and Okta and PingFederate with SAML and SCIM; SailPoint, OneLogin, Google, Microsoft AD FS and CA SSO with SAML. | F15: “Microsoft Azure AD (SAML & SCIM)” | G15: 32 | H15: 34 | I15: IdP configuration guides (any SAML 2.0 IdP) | J15: ZPA supports any SAML 2.0 IdP and publishes ZPA guides for Microsoft Entra ID (still titled Azure AD; SAML and SCIM), Okta, Microsoft AD FS 2.0/3.0, OneLogin and Ping Identity PingOne. PingFederate has a guide only as an Authentication Service external IdP. The ZPA guide index has no entry for Google, SailPoint or CA SSO. | K15: Native | L15: IdP Configuration Guides | M15: https://help.zscaler.com/zpa/authentication/idp-configuration-guides | N15: Configuration Guide for Microsoft Azure AD — https://help.zscaler.com/zpa/configuration-guide-microsoft-azure-ad SCIM Configuration Guide for Microsoft Azure AD — https://help.zscaler.com/zpa/scim-configuration-guide-microsoft-azure-ad Configuration Guide for Okta — https://help.zscaler.com/zpa/configuration-guide-okta Configuration Guide for Microsoft ADFS 2.0 and 3.0 — https://help.zscaler.com/zpa/configuration-guide-microsoft-adfs-20-and-30 Configuration Guide for Onelogin — https://help.zscaler.com/zpa/configuration-guide-onelogin Configuring PingFederate as an External IdP — https://help.zscaler.com/authentication-service/configuring-pingfederate-external-idp Configuring an IdP for Single Sign-On — https://help.zscaler.com/zpa/configuring-idp-single-sign | O15: [Configuring an IdP for Single Sign-On] “The following configuration guides provide instructions on how to configure specific IdPs for SSO, but ZPA can support any IdP.” [Configuration Guide for Microsoft Azure AD] “This guide provides information on how to set up Microsoft Azure Active Directory (AD) as a IdP for Private Access (ZPA).” [Configuration Guide for Microsoft Azure AD] “User-friendly group names are only sent to Azure AD using Azure AD Connect. For example, groups from an on-premise active directory show up in Azure AD when Azure AD Connect syncs the group information.” | P15: [Configuration Guide for Microsoft Azure AD] “A premium Azure AD subscription, or an Azure AD subscription that has used less than 10 gallery Single Sign-On (SSO) applications with the license.” [SCIM Configuration Guide for Microsoft Azure AD] “A premium Azure AD subscription” | Q15: Entra ID is the guide that applies (current-state.md). On-prem AD groups reach ZPA only through Entra sync (Azure AD Connect) — fits the one-way AD → Entra sync recorded here. | R15: 2026-10-20
A16: ZT-15 | B16: Element 1 — Who is connecting? | C16: Identity | D16: Guidance | E16: Derive the first round of user segmentation from HR or organisational structure (e.g. finance vs IT groups). | F16: “Leverage HR departments or the organizational structure to define your first round zero trust differentiation with user group segmentation” | G16: 29, 31 | H16: 31, 33 | I16: Access policy rules by SCIM group or SAML attribute (role-based access control) | J16: Map HR or organisational groups (SCIM groups, or a department attribute) to rules on segment groups — Zscaler’s own example pairs ‘Sales Staff’ with ‘Sales App and Intranet Group’. | K16: Native | L16: About Access Policy | M16: https://help.zscaler.com/zpa/about-access-policy | N16: About SCIM Groups — https://help.zscaler.com/zpa/about-scim-groups Access Policy Configuration Examples — https://help.zscaler.com/zpa/access-policy-configuration-examples | O16: [About Access Policy] “For example, you would specify the users first (i.e., Sales Staff), then specify which application segments or segment groups they can access (i.e., Sales App and Intranet Group).” | Q16: Feeds phase 3 (archetypes) and phase 5 (policy criteria per archetype) in the README. | R16: 2026-10-20
A17: ZT-16 | B17: Element 1 — Who is connecting? | C17: Identity | D17: Requirement | E17: Where initiators at a site cannot be individually authenticated (shared campus network with users, printers and devices), apply policy to the location as an identity. | F17: “by leveraging this location identity, the enterprise can define policies solely for this location” | G17: 32, 33 | H17: 34, 35 | I17: Branch/Cloud Connector groups, Locations and client types in access policy | J17: Traffic a Branch Connector forwards from a site (or a Cloud Connector from a cloud) can be matched by connector group, location or client type — policy for the location, with no user identity. | K17: Other Zscaler product | L17: About Access Policy | M17: https://help.zscaler.com/zpa/about-access-policy | N17: About Branch Connector Groups — https://help.zscaler.com/zpa/about-branch-connector-groups About Cloud Connector Groups — https://help.zscaler.com/zpa/about-cloud-connector-groups Configuring Access Policies — https://help.zscaler.com/zpa/configuring-access-policies Understanding Business Continuity — https://help.zscaler.com/zpa/understanding-business-continuity | O17: [About Access Policy] “Locations: The Branch Connector, Cloud Connector, or other locations and sublocations.” [About Access Policy] “Branch Connector Groups: The group of Branch Connectors to which the policy applies.” | P17: [Understanding Business Continuity] “Browser Access, Source IP Anchoring, Cloud Connector, and Branch Connector client types are not supported.” | Q17: Headless devices (printers, EFTPOS terminals) cannot run Client Connector; location-based policy needs Branch Connector, licensed separately (glossary). | R17: 2026-10-20
A18: ZT-17 | B18: Element 1 — Who is connecting? | C18: Workload & IoT/OT | D18: Requirement | E18: Identify workloads and IoT/OT devices that cannot authenticate to an IdP by location (site, VPC/VNet, VLAN), fingerprinting or tagging — never by IP address alone. | F18: “IoT/OT devices and workloads that cannot perform authentication against an IdP require alternative methods to validate the connection source” “Zscaler best practices recommend not using IP addresses alone as an identity value” | G18: 31, 34, 35, 45, 46 | H18: 33, 36, 37, 47, 48 | I18: Cloud/Branch Connector groups and Workload Groups as policy criteria; Zscaler Microsegmentation for host-level east-west | J18: For workload traffic forwarded into ZPA, policy identifies the source by Cloud/Branch Connector group, location or workload group rather than a user. IoT/OT fingerprinting is not described in the ZPA articles read (see Not ZPA X14); host-agent identity for east-west is Zscaler Microsegmentation. | K18: Other Zscaler product | L18: About Cloud Connector Groups | M18: https://help.zscaler.com/zpa/about-cloud-connector-groups | N18: About Access Policy — https://help.zscaler.com/zpa/about-access-policy What Is Microsegmentation? — https://help.zscaler.com/zpa/what-is-microsegmentation | O18: [About Cloud Connector Groups] “Cloud Connector groups are comprised of individual Cloud Connectors and are used to configure policy rules in the Zscaler Admin Console.” [About Access Policy] “Workload Groups: The Workload Groups from your cloud workloads.” | P18: [What Is Microsegmentation?] “If you want Microsegmentation provisioned for your organization, contact your Zscaler Account team.” | Q18: Out of scope (decision 2026-09-19). EFTPOS terminal → payment switch and agent → collector traffic is invisible to ZPA but must still be known so a user-to-app change does not break it (T-015, T-016). | R18: 2026-10-20
A19: ZT-18 | B19: Element 1 — Who is connecting? | C19: Enforcement | D19: Requirement | E19: Default deny: block until explicitly allowed, and fall back to a conditional block whenever any element's assessment cannot be met; blocks can be invoked at any stage. | F19: “access is completely blocked until explicitly allowed” “If the control assessment of Identity and Context cannot be met, the access must default, as outlined in Figure 11, to a Conditional Block policy.” | G19: 16, 28, 31, 44, 59, 75, 88, 106, 116, 147 | H19: 18, 30, 33, 46, 61, 77, 90, 108, 118, 149 | I19: Implicit Block Access in access policy; Block Access rule action | J19: If no access rule matches — or none exist — access is implicitly blocked; rules are evaluated top-down, first match, against the most specific application segment. Client forwarding policy runs first and defaults to Forward to Private Access, so a Bypass rule removes traffic before access policy (and its default block) is reached. | K19: Native | L19: Understanding Policies | M19: https://help.zscaler.com/zpa/understanding-policies | N19: Configuring Access Policies — https://help.zscaler.com/zpa/configuring-access-policies About Client Forwarding Policy — https://help.zscaler.com/zpa/about-client-forwarding-policy Understanding Private Access Session Status Codes — https://help.zscaler.com/zpa/understanding-private-access-session-status-codes | O19: [Understanding Policies] “For access policy, access to the application is implicitly set to Block Access. This is also the case if you do not define any policy rules at all within the Zscaler Admin Console.” [Configuring Access Policies] “By default, Private Access (ZPA) blocks access to applications and segment groups for users until you configure policy rules that explicitly allow access.” | P19: [Understanding Policies] “For client forwarding policy, access to the application is implicitly set to Forward to Private Access.” | Q19: README: client forwarding policy is evaluated before access policy, so a BYPASS is not a block and leaves no user activity record. ~10 BYPASS rules exist, none with an expiry (T-054). A default deny is logged with the status code for ‘no policy configured’ (Understanding Private Access Session Status Codes). | R19: 2026-10-20
A20: ZT-19 | B20: Element 2 — What are the attributes? | C20: Context & posture | D20: Requirement | E20: Distinguish trusted from untrusted and defined from undefined locations/networks (e.g. office vs home or guest network) and use that in policy. | F20: “A trusted location should be governed by enterprise-defined conditions that reduce its risk profile.” | G20: 39, 40, 42 | H20: 41, 42, 44 | I20: Client Connector Trusted Networks (access policy, client forwarding policy, forwarding profiles) | J20: Admins define trusted networks by conditions (DNS server, DNS search domains, hostname/IP resolution, network range, default gateway, DHCP server, egress IP); Client Connector detects them and the result can be used in access policy, client forwarding policy and forwarding profiles. | K20: Native | L20: Configuring Trusted Networks for Zscaler Client Connector | M20: https://help.zscaler.com/zscaler-client-connector/configuring-trusted-networks-zscaler-client-connector | N20: About Access Policy — https://help.zscaler.com/zpa/about-access-policy Configuring Forwarding Profiles for Zscaler Client Connector — https://help.zscaler.com/zscaler-client-connector/configuring-forwarding-profiles-zscaler-client-connector Configuring Access Policies — https://help.zscaler.com/zpa/configuring-access-policies | O20: [Configuring Trusted Networks for Zscaler Client Connector] “To have Zscaler Client Connector identify one of your organization’s trusted networks, you must define conditions for that network as criteria that Zscaler Client Connector uses for verification.” [About Access Policy] “Client Connector Trusted Networks: The type of network the user is connected to that Zscaler Client Connector can trust.” | P20: [Configuring Trusted Networks for Zscaler Client Connector] “If a resolution fails, the app could incorrectly determine that the network is an untrusted one, in which case it applies the wrong forwarding profile action.” [Configuring Access Policies] “The posture profiles or trusted networks criteria only work with Client Connector.” | Q20: SYDNEY LAN users are brokered through the private service edge (README). | R20: 2026-10-20
A21: ZT-20 | B21: Element 2 — What are the attributes? | C21: Context & posture | D21: Requirement | E21: Control access by geography (country), e.g. restrict access from sanctioned countries. | F21: “user access from specific sanctioned countries should be controlled” | G21: 39, 40 | H21: 41, 42 | I21: Country Codes access-policy criterion | J21: Rules can allow or block by the country the user’s public IP is located in. For a user reaching a Private Service Edge from an RFC 1918 address, the PSE’s location is used instead. | K21: Native | L21: About Access Policy | M21: https://help.zscaler.com/zpa/about-access-policy | N21: Configuring Access Policies — https://help.zscaler.com/zpa/configuring-access-policies About Private Service Edges — https://help.zscaler.com/zpa/about-private-service-edges | O21: [About Access Policy] “Country Codes: The country that a user's IP address is located in.” [About Private Service Edges] “If a user connects to a Private Service Edge with an RFC 1918 IP address, then the location of the Private Service Edge is used to evaluate policies with country criteria.” | P21: [Configuring Access Policies] “The Country Codes criteria type is not supported in Browser Access or Privileged Remote Access Applications.” | Q21: SYDNEY LAN users brokered by the PSE from RFC 1918 addresses are evaluated at the PSE’s location, not their own (About Private Service Edges). | R21: 2026-10-20
A22: ZT-21 | B22: Element 2 — What are the attributes? | C22: Context & posture | D22: Requirement | E22: Detect and stop the 'impossible traveller' (access from distant locations in quick succession). | F22: “Geographic controls can also be used to stop the “impossible traveler”” | G22: 40, 72 | H22: 42, 74 | I22: None native. Nearest: Risk Scores criterion (user risk from Internet & SaaS); Adaptive Access profiles | J22: No impossible-travel or geovelocity signal appears in the ZPA or Adaptive Access Engine articles read. ZPA can consume a user risk score computed by Internet & SaaS, and Adaptive Access profiles, but neither article says impossible travel feeds them. The control has to come from a risk engine outside ZPA. | K22: Gap | L22: About User Risk Scores | M22: https://help.zscaler.com/zpa/about-user-risk-scores | N22: Understanding Adaptive Access Engine — https://help.zscaler.com/unified/understanding-adaptive-access-engine Understanding User Risk Score — https://help.zscaler.com/zia/understanding-user-risk-score | O22: [About User Risk Scores] “User risk scores are generated based on a user’s DLP violations, risky behavior, unsanctioned cloud application usage, and other suspicious factors.” [About User Risk Scores] “You can add user risk scores as a criteria type to access policy rules.” | P22: [About User Risk Scores] “User risk scores are not supported in User Portals or Privileged Remote Access Portals.” | R22: 2026-10-20
A23: ZT-22 | B23: Element 2 — What are the attributes? | C23: Context & posture | D23: Requirement | E23: Use time of request (within or outside defined time bands, e.g. business hours) as a policy condition. | F23: “The time that a user requests a connection to an application is another attribute zero trust architecture can base policy on.” | G23: 39, 41 | H23: 41, 43 | I23: None — no time-of-day criterion in access policy | J23: Access-policy criteria (Who / What / Where) contain no time-of-day or schedule condition. The nearest time-bound controls are timeout policy (re-authentication and idle timeouts) and PRA privileged approvals with a start and end time for named users. | K23: Gap | L23: Configuring Access Policies | M23: https://help.zscaler.com/zpa/configuring-access-policies | N23: Configuring Timeout Policies — https://help.zscaler.com/zpa/configuring-timeout-policies About Privileged Approvals — https://help.zscaler.com/zpa/about-privileged-approvals | O23: [Configuring Access Policies] Criteria as listed — Who: SAML and SCIM Attributes; External IAM IdPs. What: Applications; Branch Connector Groups; Chrome Enterprise Browser; Client Connector Posture Profiles; Client Connector Trusted Networks; Client Types; Cloud Connector Groups; Federated Applications; Machine Groups; Platforms; Risk Scores. Where: Country Codes; Extranet Location; Locations. [About Privileged Approvals] “Create privileged approvals with a set amount of time that one or more designated application segments can be accessed.” | P23: [About Privileged Approvals] “Privileged approvals allow third-party users and contractors to be able to log in to a Privileged Remote Access (PRA) Portal.” | R23: 2026-10-20
A24: ZT-23 | B24: Element 2 — What are the attributes? | C24: Context & posture | D24: Requirement | E24: Differentiate managed (corporate) from unmanaged (BYOD, contractor) devices and restrict untrusted devices appropriately. | F24: “we must further differentiate between managed and unmanaged devices” “The personal device must be identified as untrusted and access restricted appropriately.” | G24: 33, 41, 42, 43, 44 | H24: 35, 43, 44, 45, 46 | I24: Client Types + Client Connector posture profiles | J24: There is no single ‘managed device’ criterion. Pattern implied by the criteria: Client Connector client type plus a verified posture profile (e.g. Domain Joined, AzureAD Domain Joined, Client Certificate) for managed devices; the Web Browser client type for unmanaged ones, where posture and trusted-network criteria cannot be used. | K24: Native | L24: Configuring Access Policies | M24: https://help.zscaler.com/zpa/configuring-access-policies | N24: About Access Policy — https://help.zscaler.com/zpa/about-access-policy Configuring Device Posture Profiles — https://help.zscaler.com/zscaler-client-connector/configuring-device-posture-profiles | O24: [Configuring Access Policies] “Rules using the Web Browser or Internet & SaaS Service Edge client types additionally can't use posture profiles or trusted networks criteria.” [About Access Policy] “Client Connector Posture Profiles: Zscaler Client Connector device posture profiles are the set of criteria that a user's device must meet to access applications with Private Access.” | Q24: With Browser Access out of scope, an unmanaged device is refused rather than restricted (decision 2026-09-27). | R24: 2026-10-20
A25: ZT-24 | B25: Element 2 — What are the attributes? | C25: Context & posture | D25: Requirement | E25: Assess device posture — operating system, antivirus, EDR presence, domain membership, disk encryption — evaluated by the endpoint agent without calling out to external sources. | F25: “without having to call out to external sources for validation” | G25: 41, 42, 72 | H25: 43, 44, 74 | I25: Client Connector device posture profiles | J25: Client Connector evaluates posture on the device — OS Version, Detect Antivirus, Detect Microsoft Defender / CrowdStrike / SentinelOne / Carbon Black, Firewall, Full Disk Encryption, Domain Joined and more — every 2–15 minutes (EDR and process checks immediately on change). Access policy sees only the outcome. | K25: Native | L25: Configuring Device Posture Profiles | M25: https://help.zscaler.com/zscaler-client-connector/configuring-device-posture-profiles | N25: About Device Posture Profiles — https://help.zscaler.com/zscaler-client-connector/about-device-posture-profiles About Access Policy — https://help.zscaler.com/zpa/about-access-policy | O25: [Configuring Device Posture Profiles] “For each posture type, select how often Zscaler Client Connector evaluates device posture by selecting a value, in one-minute intervals, from the drop-down menu. The maximum default value is 15 minutes. The minimum value is 2 minutes.” | P25: [Configuring Device Posture Profiles] “Not all device posture types work for all platforms.” [Configuring Device Posture Profiles] “Zscaler Client Connector doesn't check for the presence of third-party firewalls. Third-party firewalls don't fulfill the posture check requirement.” | Q25: backlog T-053 treats a posture failure as a distinct onboarding-failure cause. | R25: 2026-10-20
A26: ZT-25 | B26: Element 2 — What are the attributes? | C26: Context & posture | D26: Requirement | E26: Validate a client certificate as proof of a managed device. | F26: “client certificate validation” | G26: 42, 72 | H26: 44, 74 | I26: Client Certificate, Certificate Trust and Server Validated Client Certificate posture types | J26: Posture profiles can require a client certificate on the device; the Server Validated Client Certificate type applies to Private Access only. | K26: Native | L26: Configuring Device Posture Profiles | M26: https://help.zscaler.com/zscaler-client-connector/configuring-device-posture-profiles | O26: [Configuring Device Posture Profiles] Posture types listed include Client Certificate, Certificate Trust and Server Validated Client Certificate. [Configuring Device Posture Profiles] “This posture is applicable to Private Access (ZPA) only.” | P26: [Configuring Device Posture Profiles] “As of Zscaler Client Connector version 5.0 for Android, Zscaler is ending support for the Client Certificate posture type for all Android devices.” [Configuring Device Posture Profiles] “Client certificates that require user interaction (e.g., smart cards with a PIN) are not supported.” | R26: 2026-10-20
A27: ZT-26 | B27: Element 2 — What are the attributes? | C27: Context & posture | D27: Requirement | E27: Integrate third-party EDR/AV (and other security tools) via API to enrich device and risk context. | F27: “sometimes via APIs from other third-party systems like endpoint detection and response (EDR) vendors” “Those garnered from EDR, SIEM, or SOAR services may add context for improved determinations.” | G27: 33, 42, 75, 81 | H27: 35, 44, 77, 83 | I27: EDR posture checks (CrowdStrike ZTA score; Defender, SentinelOne, Carbon Black detection; Jamf risk) and Adaptive Access Engine integrations | J27: Two mechanisms. On the device, posture checks test a CrowdStrike ZTA score threshold, presence of Defender, SentinelOne or Carbon Black, or a Jamf risk level. In the cloud, the Adaptive Access Engine ingests CrowdStrike and Microsoft Defender signals into Adaptive Access profiles usable in ZPA policy. | K27: Dependency | L27: Configuring Device Posture Profiles | M27: https://help.zscaler.com/zscaler-client-connector/configuring-device-posture-profiles | N27: Integrating CrowdStrike with Adaptive Access Engine — https://help.zscaler.com/unified/integrating-crowdstrike-adaptive-access-engine Integrating Microsoft Defender with Adaptive Access Engine — https://help.zscaler.com/unified/integrating-microsoft-defender-adaptive-access-engine Understanding Adaptive Access Engine — https://help.zscaler.com/unified/understanding-adaptive-access-engine | O27: [Configuring Device Posture Profiles] “Zscaler Client Connector compares this number against an overall score (a combined score based on the device OS settings and sensor settings) assigned by CrowdStrike's user agent. If that overall score is greater than or equal to the score you've entered, the posture check passes.” [Integrating Microsoft Defender with Adaptive Access Engine] “Risk Score: Values are None, Informational, Low, Medium, and High.” | P27: [Configuring Device Posture Profiles] “Users must enable the CrowdStrike ZTA feature in CrowdStrike. Contact CrowdStrike Support to enable this feature.” [Integrating CrowdStrike with Adaptive Access Engine] “This integration is in limited availability. Contact Zscaler Support for assistance.” [Integrating Microsoft Defender with Adaptive Access Engine] “A Microsoft Azure account with subscription for Event Hub and Logic App.” [Understanding Adaptive Access Engine] “Authentication Service for end users is enabled or end user migration to Authentication Service is completed.” | R27: 2026-10-20
A28: ZT-27 | B28: Element 2 — What are the attributes? | C28: Context & posture | D28: Requirement | E28: Detect jailbroken (or rooted) handhelds. | F28: “jailbroken or not (for handhelds)” | G28: 42 | H28: 44 | I28: Unauthorized Modification posture type (Android, iOS) | J28: Client Connector checks mobile devices for jailbreaking or rooting. | K28: Native | L28: Configuring Device Posture Profiles | M28: https://help.zscaler.com/zscaler-client-connector/configuring-device-posture-profiles | O28: [Configuring Device Posture Profiles] “Zscaler Client Connector checks for unauthorized modifications on the device, such as jailbreaking or rooting.” | R28: 2026-10-20
A29: ZT-28 | B29: Element 2 — What are the attributes? | C29: Context & posture | D29: Requirement | E29: Combine multiple ('stacked') posture tests into one outcome consumed by policy. | F29: “Having these variations of stacked device posture tests allows an enterprise to consume the outcomes of these posture assessments as an additional layer of user context” | G29: 42 | H29: 44 | I29: Multiple criteria per rule with Boolean AND/OR | J29: A rule can combine several posture profiles with other context; a request must match all of a rule’s conditions, so stacked tests resolve to one allow/block outcome. | K29: Native | L29: About Access Policy | M29: https://help.zscaler.com/zpa/about-access-policy | N29: Configuring Access Policies — https://help.zscaler.com/zpa/configuring-access-policies | O29: [About Access Policy] “A user's application request must match all the conditions within a policy rule.” [About Access Policy] “Access Policy rules use AND and OR operators only.” | R29: 2026-10-20
A30: ZT-29 | B30: Element 3 — Where is the connection going? | C30: Application definition | D30: Requirement | E30: Define internal applications explicitly — by name (FQDN, internal domains) or private IP — and cover web and non-web (SSH, RDP, other TCP/UDP) protocols. | F30: “These apps exist in internal address spaces, e.g., server1.local, or on a private IP (RFC-1918) space.” “Customers can also manually create and modify their own app segments based on their application classification requirements.” | G30: 48, 54, 57, 63, 65 | H30: 50, 56, 59, 65, 67 | I30: Application segments (defined applications) | J30: An application segment defines apps by FQDN, IP address, local domain or wildcard domain (IP subnets for discovery), with TCP and UDP port ranges, so web and non-web protocols are covered. | K30: Native | L30: Configuring Defined Application Segments | M30: https://help.zscaler.com/zpa/configuring-defined-application-segments | N30: About Applications — https://help.zscaler.com/zpa/about-applications Application Discovery Deployment and Operations Guide — https://help.zscaler.com/zscaler-deployments-operations/application-discovery-deployment-and-operations-guide | O30: [Configuring Defined Application Segments] “Enter a fully qualified domain name (FQDN), IP address, local domain, or a wildcard domain (e.g., *.safemarch.com) associated with the application.” [Configuring Defined Application Segments] “TCP Port Ranges: Enter the TCP port ranges that can be used to access the application.” [Configuring Defined Application Segments] “UDP Port Ranges: Enter the UDP port ranges that can be used to access the application.” | P30: [Configuring Defined Application Segments] “You can't define an application with hyphenated IP address ranges (e.g., 192.168.0.1–10).” | Q30: README lever: tight = specific FQDN + specific ports; loose = wildcard FQDN, broad CIDR, 1-65535. Exact match pulls a destination out of the wildcard the moment a narrower segment exists, so each replacement segment needs its full port set before it is built (destination-port-profile.spl). | R30: 2026-10-20
